I'm sorry, but an uncaught exception occurred.

While running game code:
  File "game/ScriptAndCases/Case_1/Case1script.rpy", line 330, in script
    if attack():
  File "game/ScriptAndCases/Case_1/Case1script.rpy", line 330, in <module>
    if attack():
NameError: name 'attack' is not defined

-- Full Traceback ------------------------------------------------------------

Full traceback:
  File "game/ScriptAndCases/Case_1/Case1script.rpy", line 330, in script
    if attack():
  File "D:\truc\renpy-8.1.3-sdk\renpy\ast.py", line 2133, in execute
    if renpy.python.py_eval(condition):
  File "D:\truc\renpy-8.1.3-sdk\renpy\python.py", line 1153, in py_eval
    return py_eval_bytecode(code, globals, locals)
  File "D:\truc\renpy-8.1.3-sdk\renpy\python.py", line 1146, in py_eval_bytecode
    return eval(bytecode, globals, locals)
  File "game/ScriptAndCases/Case_1/Case1script.rpy", line 330, in <module>
    if attack():
NameError: name 'attack' is not defined

Windows-10-10.0.19045 AMD64
Ren'Py 8.1.3.23091805
Ace Attorney: Walter Romanng  Beta
Tue Jun  4 19:00:22 2024
